Workbook
Name Pagamento: Set!$F$2:$F$3
Name Compra: Set!$B$2:$B$3
Name Avaliados: Set!$D$2:$D$3

Sheet Calcular
B1: Tipo de Compra | E1: Pagamento | F1: Total | K1: z | M1: 1775679826593 | N1: 1782854443666 | O1: Olá isadora! *Avaliação Mania* 1782854443666 2. macaquinho 3. vestido 4. blazer 5. blazer 6. blusa modal 7. macaquinho 8. vestido 9. calça 10. calça 11. calça 12. calça 13. cinta 14. blusa 15. blusa 16. blusa 17. blusa 18. blusa 19. blusa 20. blusa 21. casaco 22. vestido 23. short 24. short 25. short 26. short 27. short 28. short 29. short 30. short 31. academia b 32. short 33. short 34. saia 35. saia 36. saia 37. saia 38. saia 39. blusa 40. blusa 41. blusa 42. blusa 43. blusa 44. blusa 45. blusa 46. blusa 47. blusa 48. blusa 49. top 50. body 51. academia 52. academia 53. academia 54. academia 55. academia 56. academia 57. academia 58. camiseta 59. camiseta 60. camiseta 61. camiseta 62. melissa possession 63. botero sandalia Total em Dinheiro: ou *Em Créditos na Loja: *R$407,50* - Assumimos o frete para envio cliente ➡loja. - Essa avaliação é baseada no valor das melissas em perfeitas condições e sem avarias ou detalhes. - A recepção e conferência da chegada é sempre filmada e disponibilizada para o cliente.
A2: isadora | B2: Avaliados | E2: Em Dinheiro | F2: =IF(AND(B2="Direta", B4="N/A"),SUM(I7:I72)+N4,IF(AND(B2="Avaliados",B4="Do Clube"),"Clube: só em Creditos", IF(AND(B2="Avaliados",B4="Fora do Clube"),(SUM(N8:N72))-(SUM(N8:N72)*60%)-N4,"-")) ) -> 0 | K2: Altura | L2: =(Set!J2+((E5-1)*0.8)) -> 11.2
B3: Tipo de Fornecedor | E3: Em Credito | F3: =IF(AND(B2="Direta" , B4="N/A"),"Direta: só Em Dinheiro",IF(AND(B2="Avaliados",B4="Do Clube"),(SUM(N8:N72))-(SUM(N8:N72)*20%)-N4, IF(AND(B2="Avaliados",B4="Fora do Clube"),(SUM(N8:N72))-(SUM(N8:N72)*40%)-N4,"-")) ) -> 0 | H3: Valor da Venda(na Compra Direta) | K3: Largura | L3: =(Set!J3+((E5-1)*1)) -> 20.8
B4: Fora do Clube | K4: Comprimento | L4: =(Set!J4+((E5-1)*1.3)) -> 30.2
E5: =COUNTIF(N8:N72,">0") -> 0 | F5: Valor de Compra | K5: Peso | L5: =Set!J5+(($E$5-1)*0.5) -> 0
D6: Min | E6: Fabricação | F6: Em Dinheiro | G6: Em Credito
G7: =IF(N8="","-",IF(AND($B$2="Direta" , $B$4="N/A"),"Só Em Dinheiro",IF(AND($B$2="Avaliados",$B$4="Do Clube"),N8-(N8*20%)-($N$4/$E$5),IF(AND($B$2="Avaliados",$B$4="Fora do Clube"),N8-(N8*40%)-($N$4/$E$5),"-")) )) -> - | H7: =$N$4/$E$5 -> #DIV/0! | I7: =IF($B$2="Avaliados",H7-H7,N8*'Precificação'!$C$38) -> #DIV/0! | J7: =IF(I7>0,H7+I7,0) -> #DIV/0!
A8: macaquinho | C8: 35 | G8: =IF(N9="","-",IF(AND($B$2="Direta" , $B$4="N/A"),"Só Em Dinheiro",IF(AND($B$2="Avaliados",$B$4="Do Clube"),N9-(N9*20%)-($N$4/$E$5),IF(AND($B$2="Avaliados",$B$4="Fora do Clube"),N9-(N9*40%)-($N$4/$E$5),"-")) )) -> - | H8: =$N$4/$E$5 -> #DIV/0! | I8: =IF($B$2="Avaliados",H8-H8,N9*'Precificação'!$C$38) -> #DIV/0! | J8: =IF(I8>0,H8+I8,0) -> #DIV/0!
A9: vestido | C9: 35 | D9: 0 | G9: =IF(N10="","-",IF(AND($B$2="Direta" , $B$4="N/A"),"Só Em Dinheiro",IF(AND($B$2="Avaliados",$B$4="Do Clube"),N10-(N10*20%)-($N$4/$E$5),IF(AND($B$2="Avaliados",$B$4="Fora do Clube"),N10-(N10*40%)-($N$4/$E$5),"-")) )) -> - | H9: =$N$4/$E$5 -> #DIV/0! | I9: =IF($B$2="Avaliados",H9-H9,N10*'Precificação'!$C$38) -> #DIV/0! | J9: =IF(I9>0,H9+I9,0) -> #DIV/0!
A10: blazer | C10: 35 | D10: 0 | G10: =IF(N11="","-",IF(AND($B$2="Direta" , $B$4="N/A"),"Só Em Dinheiro",IF(AND($B$2="Avaliados",$B$4="Do Clube"),N11-(N11*20%)-($N$4/$E$5),IF(AND($B$2="Avaliados",$B$4="Fora do Clube"),N11-(N11*40%)-($N$4/$E$5),"-")) )) -> - | H10: =$N$4/$E$5 -> #DIV/0! | I10: =IF($B$2="Avaliados",H10-H10,N11*'Precificação'!$C$38) -> #DIV/0! | J10: =IF(I10>0,H10+I10,0) -> #DIV/0!
A11: blazer | C11: 35 | D11: 0 | G11: =IF(#REF!="","-",IF(AND($B$2="Direta" , $B$4="N/A"),"Só Em Dinheiro",IF(AND($B$2="Avaliados",$B$4="Do Clube"),#REF!-(#REF!*20%)-($N$4/$E$5),IF(AND($B$2="Avaliados",$B$4="Fora do Clube"),#REF!-(#REF!*40%)-($N$4/$E$5),"-")) )) -> #REF! | H11: =$N$4/$E$5 -> #DIV/0! | I11: =IF($B$2="Avaliados",H11-H11,#REF!*'Precificação'!$C$38) -> #DIV/0! | J11: =IF(I11>0,H11+I11,0) -> #DIV/0!
A12: blusa modal | C12: 30 | D12: =MINIFS('Variação'!I:I,'Variação'!B:B,B12) -> 0 | G12: =IF(N12="","-",IF(AND($B$2="Direta" , $B$4="N/A"),"Só Em Dinheiro",IF(AND($B$2="Avaliados",$B$4="Do Clube"),N12-(N12*20%)-($N$4/$E$5),IF(AND($B$2="Avaliados",$B$4="Fora do Clube"),N12-(N12*40%)-($N$4/$E$5),"-")) )) -> - | H12: =$N$4/$E$5 -> #DIV/0! | I12: =IF($B$2="Avaliados",H12-H12,N12*'Precificação'!$C$38) -> #DIV/0! | J12: =IF(I12>0,H12+I12,0) -> #DIV/0!
A13: macaquinho | C13: 30 | D13: =MINIFS('Variação'!I:I,'Variação'!B:B,B13) -> 0 | G13: =IF(N13="","-",IF(AND($B$2="Direta" , $B$4="N/A"),"Só Em Dinheiro",IF(AND($B$2="Avaliados",$B$4="Do Clube"),N13-(N13*20%)-($N$4/$E$5),IF(AND($B$2="Avaliados",$B$4="Fora do Clube"),N13-(N13*40%)-($N$4/$E$5),"-")) )) -> - | H13: =$N$4/$E$5 -> #DIV/0! | I13: =IF($B$2="Avaliados",H13-H13,N13*'Precificação'!$C$38) -> #DIV/0! | J13: =IF(I13>0,H13+I13,0) -> #DIV/0!
A14: vestido | C14: 25 | D14: =MINIFS('Variação'!I:I,'Variação'!B:B,B14) -> 0 | G14: =IF(N14="","-",IF(AND($B$2="Direta" , $B$4="N/A"),"Só Em Dinheiro",IF(AND($B$2="Avaliados",$B$4="Do Clube"),N14-(N14*20%)-($N$4/$E$5),IF(AND($B$2="Avaliados",$B$4="Fora do Clube"),N14-(N14*40%)-($N$4/$E$5),"-")) )) -> - | H14: =$N$4/$E$5 -> #DIV/0! | I14: =IF($B$2="Avaliados",H14-H14,N14*'Precificação'!$C$38) -> #DIV/0! | J14: =IF(I14>0,H14+I14,0) -> #DIV/0!
A15: calça | C15: 25 | D15: =MINIFS('Variação'!I:I,'Variação'!B:B,B15) -> 0 | G15: =IF(N15="","-",IF(AND($B$2="Direta" , $B$4="N/A"),"Só Em Dinheiro",IF(AND($B$2="Avaliados",$B$4="Do Clube"),N15-(N15*20%)-($N$4/$E$5),IF(AND($B$2="Avaliados",$B$4="Fora do Clube"),N15-(N15*40%)-($N$4/$E$5),"-")) )) -> - | H15: =$N$4/$E$5 -> #DIV/0! | I15: =IF($B$2="Avaliados",H15-H15,N15*'Precificação'!$C$38) -> #DIV/0! | J15: =IF(I15>0,H15+I15,0) -> #DIV/0!
A16: calça | C16: 25 | D16: =MINIFS('Variação'!I:I,'Variação'!B:B,B16) -> 0 | G16: =IF(N16="","-",IF(AND($B$2="Direta" , $B$4="N/A"),"Só Em Dinheiro",IF(AND($B$2="Avaliados",$B$4="Do Clube"),N16-(N16*20%)-($N$4/$E$5),IF(AND($B$2="Avaliados",$B$4="Fora do Clube"),N16-(N16*40%)-($N$4/$E$5),"-")) )) -> - | H16: =$N$4/$E$5 -> #DIV/0! | I16: =IF($B$2="Avaliados",H16-H16,N16*'Precificação'!$C$38) -> #DIV/0! | J16: =IF(I16>0,H16+I16,0) -> #DIV/0!
A17: calça | C17: 25 | D17: =MINIFS('Variação'!I:I,'Variação'!B:B,B17) -> 0 | G17: =IF(N17="","-",IF(AND($B$2="Direta" , $B$4="N/A"),"Só Em Dinheiro",IF(AND($B$2="Avaliados",$B$4="Do Clube"),N17-(N17*20%)-($N$4/$E$5),IF(AND($B$2="Avaliados",$B$4="Fora do Clube"),N17-(N17*40%)-($N$4/$E$5),"-")) )) -> - | H17: =$N$4/$E$5 -> #DIV/0! | I17: =IF($B$2="Avaliados",H17-H17,N17*'Precificação'!$C$38) -> #DIV/0! | J17: =IF(I17>0,H17+I17,0) -> #DIV/0!
A18: calça | C18: 25 | D18: =MINIFS('Variação'!I:I,'Variação'!B:B,B18) -> 0 | G18: =IF(N18="","-",IF(AND($B$2="Direta" , $B$4="N/A"),"Só Em Dinheiro",IF(AND($B$2="Avaliados",$B$4="Do Clube"),N18-(N18*20%)-($N$4/$E$5),IF(AND($B$2="Avaliados",$B$4="Fora do Clube"),N18-(N18*40%)-($N$4/$E$5),"-")) )) -> - | H18: =$N$4/$E$5 -> #DIV/0! | I18: =IF($B$2="Avaliados",H18-H18,N18*'Precificação'!$C$38) -> #DIV/0! | J18: =IF(I18>0,H18+I18,0) -> #DIV/0!
A19: cinta | C19: 25 | D19: =MINIFS('Variação'!I:I,'Variação'!B:B,B19) -> 0 | G19: =IF(N19="","-",IF(AND($B$2="Direta" , $B$4="N/A"),"Só Em Dinheiro",IF(AND($B$2="Avaliados",$B$4="Do Clube"),N19-(N19*20%)-($N$4/$E$5),IF(AND($B$2="Avaliados",$B$4="Fora do Clube"),N19-(N19*40%)-($N$4/$E$5),"-")) )) -> - | H19: =$N$4/$E$5 -> #DIV/0! | I19: =IF($B$2="Avaliados",H19-H19,N19*'Precificação'!$C$38) -> #DIV/0! | J19: =IF(I19>0,H19+I19,0) -> #DIV/0!
A20: blusa | C20: 25 | D20: =MINIFS('Variação'!I:I,'Variação'!B:B,B20) -> 0 | G20: =IF(N20="","-",IF(AND($B$2="Direta" , $B$4="N/A"),"Só Em Dinheiro",IF(AND($B$2="Avaliados",$B$4="Do Clube"),N20-(N20*20%)-($N$4/$E$5),IF(AND($B$2="Avaliados",$B$4="Fora do Clube"),N20-(N20*40%)-($N$4/$E$5),"-")) )) -> - | H20: =$N$4/$E$5 -> #DIV/0! | I20: =IF($B$2="Avaliados",H20-H20,N20*'Precificação'!$C$38) -> #DIV/0! | J20: =IF(I20>0,H20+I20,0) -> #DIV/0!
A21: blusa | C21: 25 | D21: =MINIFS('Variação'!I:I,'Variação'!B:B,B21) -> 0 | G21: =IF(N21="","-",IF(AND($B$2="Direta" , $B$4="N/A"),"Só Em Dinheiro",IF(AND($B$2="Avaliados",$B$4="Do Clube"),N21-(N21*20%)-($N$4/$E$5),IF(AND($B$2="Avaliados",$B$4="Fora do Clube"),N21-(N21*40%)-($N$4/$E$5),"-")) )) -> - | H21: =$N$4/$E$5 -> #DIV/0! | I21: =IF($B$2="Avaliados",H21-H21,N21*'Precificação'!$C$38) -> #DIV/0! | J21: =IF(I21>0,H21+I21,0) -> #DIV/0!
A22: blusa | C22: 25 | G22: =IF(N22="","-",IF(AND($B$2="Direta" , $B$4="N/A"),"Só Em Dinheiro",IF(AND($B$2="Avaliados",$B$4="Do Clube"),N22-(N22*20%)-($N$4/$E$5),IF(AND($B$2="Avaliados",$B$4="Fora do Clube"),N22-(N22*40%)-($N$4/$E$5),"-")) )) -> - | H22: =$N$4/$E$5 -> #DIV/0! | I22: =IF($B$2="Avaliados",H22-H22,N22*'Precificação'!$C$38) -> #DIV/0! | J22: =IF(I22>0,H22+I22,0) -> #DIV/0!
A23: blusa | C23: 25 | D23: =MINIFS('Variação'!I:I,'Variação'!B:B,B23) -> 0 | G23: =IF(N23="","-",IF(AND($B$2="Direta" , $B$4="N/A"),"Só Em Dinheiro",IF(AND($B$2="Avaliados",$B$4="Do Clube"),N23-(N23*20%)-($N$4/$E$5),IF(AND($B$2="Avaliados",$B$4="Fora do Clube"),N23-(N23*40%)-($N$4/$E$5),"-")) )) -> - | H23: =$N$4/$E$5 -> #DIV/0! | I23: =IF($B$2="Avaliados",H23-H23,N23*'Precificação'!$C$38) -> #DIV/0! | J23: =IF(I23>0,H23+I23,0) -> #DIV/0!
A24: blusa | C24: 25 | D24: =MINIFS('Variação'!I:I,'Variação'!B:B,B24) -> 0 | G24: =IF(N24="","-",IF(AND($B$2="Direta" , $B$4="N/A"),"Só Em Dinheiro",IF(AND($B$2="Avaliados",$B$4="Do Clube"),N24-(N24*20%)-($N$4/$E$5),IF(AND($B$2="Avaliados",$B$4="Fora do Clube"),N24-(N24*40%)-($N$4/$E$5),"-")) )) -> - | H24: =$N$4/$E$5 -> #DIV/0! | I24: =IF($B$2="Avaliados",H24-H24,N24*'Precificação'!$C$38) -> #DIV/0! | J24: =IF(I24>0,H24+I24,0) -> #DIV/0!
A25: blusa | C25: 25 | D25: =MINIFS('Variação'!I:I,'Variação'!B:B,B25) -> 0 | G25: =IF(N25="","-",IF(AND($B$2="Direta" , $B$4="N/A"),"Só Em Dinheiro",IF(AND($B$2="Avaliados",$B$4="Do Clube"),N25-(N25*20%)-($N$4/$E$5),IF(AND($B$2="Avaliados",$B$4="Fora do Clube"),N25-(N25*40%)-($N$4/$E$5),"-")) )) -> - | H25: =$N$4/$E$5 -> #DIV/0! | I25: =IF($B$2="Avaliados",H25-H25,N25*'Precificação'!$C$38) -> #DIV/0! | J25: =IF(I25>0,H25+I25,0) -> #DIV/0!
A26: blusa | C26: 25 | D26: =MINIFS('Variação'!I:I,'Variação'!B:B,B26) -> 0 | G26: =IF(N26="","-",IF(AND($B$2="Direta" , $B$4="N/A"),"Só Em Dinheiro",IF(AND($B$2="Avaliados",$B$4="Do Clube"),N26-(N26*20%)-($N$4/$E$5),IF(AND($B$2="Avaliados",$B$4="Fora do Clube"),N26-(N26*40%)-($N$4/$E$5),"-")) )) -> - | H26: =$N$4/$E$5 -> #DIV/0! | I26: =IF($B$2="Avaliados",H26-H26,N26*'Precificação'!$C$38) -> #DIV/0! | J26: =IF(I26>0,H26+I26,0) -> #DIV/0!
A27: casaco | C27: 25 | D27: =MINIFS('Variação'!I:I,'Variação'!B:B,B27) -> 0 | G27: =IF(N27="","-",IF(AND($B$2="Direta" , $B$4="N/A"),"Só Em Dinheiro",IF(AND($B$2="Avaliados",$B$4="Do Clube"),N27-(N27*20%)-($N$4/$E$5),IF(AND($B$2="Avaliados",$B$4="Fora do Clube"),N27-(N27*40%)-($N$4/$E$5),"-")) )) -> - | H27: =$N$4/$E$5 -> #DIV/0! | I27: =IF($B$2="Avaliados",H27-H27,N27*'Precificação'!$C$38) -> #DIV/0! | J27: =IF(I27>0,H27+I27,0) -> #DIV/0!
A28: vestido | C28: 25 | D28: =MINIFS('Variação'!I:I,'Variação'!B:B,B28) -> 0 | G28: =IF(N28="","-",IF(AND($B$2="Direta" , $B$4="N/A"),"Só Em Dinheiro",IF(AND($B$2="Avaliados",$B$4="Do Clube"),N28-(N28*20%)-($N$4/$E$5),IF(AND($B$2="Avaliados",$B$4="Fora do Clube"),N28-(N28*40%)-($N$4/$E$5),"-")) )) -> - | H28: =$N$4/$E$5 -> #DIV/0! | I28: =IF($B$2="Avaliados",H28-H28,N28*'Precificação'!$C$38) -> #DIV/0! | J28: =IF(I28>0,H28+I28,0) -> #DIV/0!
A29: short | C29: 25 | D29: =MINIFS('Variação'!I:I,'Variação'!B:B,B29) -> 0 | G29: =IF(N29="","-",IF(AND($B$2="Direta" , $B$4="N/A"),"Só Em Dinheiro",IF(AND($B$2="Avaliados",$B$4="Do Clube"),N29-(N29*20%)-($N$4/$E$5),IF(AND($B$2="Avaliados",$B$4="Fora do Clube"),N29-(N29*40%)-($N$4/$E$5),"-")) )) -> - | H29: =$N$4/$E$5 -> #DIV/0! | I29: =IF($B$2="Avaliados",H29-H29,N29*'Precificação'!$C$38) -> #DIV/0! | J29: =IF(I29>0,H29+I29,0) -> #DIV/0!
A30: short | C30: 25 | D30: =MINIFS('Variação'!I:I,'Variação'!B:B,B30) -> 0 | G30: =IF(N30="","-",IF(AND($B$2="Direta" , $B$4="N/A"),"Só Em Dinheiro",IF(AND($B$2="Avaliados",$B$4="Do Clube"),N30-(N30*20%)-($N$4/$E$5),IF(AND($B$2="Avaliados",$B$4="Fora do Clube"),N30-(N30*40%)-($N$4/$E$5),"-")) )) -> - | H30: =$N$4/$E$5 -> #DIV/0! | I30: =IF($B$2="Avaliados",H30-H30,N30*'Precificação'!$C$38) -> #DIV/0! | J30: =IF(I30>0,H30+I30,0) -> #DIV/0!
A31: short | C31: 25 | D31: =MINIFS('Variação'!I:I,'Variação'!B:B,B31) -> 0 | G31: =IF(N31="","-",IF(AND($B$2="Direta" , $B$4="N/A"),"Só Em Dinheiro",IF(AND($B$2="Avaliados",$B$4="Do Clube"),N31-(N31*20%)-($N$4/$E$5),IF(AND($B$2="Avaliados",$B$4="Fora do Clube"),N31-(N31*40%)-($N$4/$E$5),"-")) )) -> - | H31: =$N$4/$E$5 -> #DIV/0! | I31: =IF($B$2="Avaliados",H31-H31,N31*'Precificação'!$C$38) -> #DIV/0!
A32: short | C32: 25 | G32: =IF(N32="","-",IF(AND($B$2="Direta" , $B$4="N/A"),"Só Em Dinheiro",IF(AND($B$2="Avaliados",$B$4="Do Clube"),N32-(N32*20%)-($N$4/$E$5),IF(AND($B$2="Avaliados",$B$4="Fora do Clube"),N32-(N32*40%)-($N$4/$E$5),"-")) )) -> - | H32: =$N$4/$E$5 -> #DIV/0! | I32: =IF($B$2="Avaliados",H32-H32,N32*'Precificação'!$C$38) -> #DIV/0! | J32: =IF(I32>0,H32+I32,0) -> #DIV/0!
A33: short | C33: 25 | D33: =MINIFS('Variação'!I:I,'Variação'!B:B,B33) -> 0 | G33: =IF(N33="","-",IF(AND($B$2="Direta" , $B$4="N/A"),"Só Em Dinheiro",IF(AND($B$2="Avaliados",$B$4="Do Clube"),N33-(N33*20%)-($N$4/$E$5),IF(AND($B$2="Avaliados",$B$4="Fora do Clube"),N33-(N33*40%)-($N$4/$E$5),"-")) )) -> - | H33: =$N$4/$E$5 -> #DIV/0! | I33: =IF($B$2="Avaliados",H33-H33,N33*'Precificação'!$C$38) -> #DIV/0!
A34: short | C34: 25 | D34: =MINIFS('Variação'!I:I,'Variação'!B:B,B34) -> 0 | G34: =IF(N34="","-",IF(AND($B$2="Direta" , $B$4="N/A"),"Só Em Dinheiro",IF(AND($B$2="Avaliados",$B$4="Do Clube"),N34-(N34*20%)-($N$4/$E$5),IF(AND($B$2="Avaliados",$B$4="Fora do Clube"),N34-(N34*40%)-($N$4/$E$5),"-")) )) -> - | H34: =$N$4/$E$5 -> #DIV/0! | I34: =IF($B$2="Avaliados",H34-H34,N34*'Precificação'!$C$38) -> #DIV/0! | J34: =IF(I34>0,H34+I34,0) -> #DIV/0!
A35: short | C35: 25
A36: short | C36: 25 | D36: =MINIFS('Variação'!I:I,'Variação'!B:B,B36) -> 0 | G36: =IF(N36="","-",IF(AND($B$2="Direta" , $B$4="N/A"),"Só Em Dinheiro",IF(AND($B$2="Avaliados",$B$4="Do Clube"),N36-(N36*20%)-($N$4/$E$5),IF(AND($B$2="Avaliados",$B$4="Fora do Clube"),N36-(N36*40%)-($N$4/$E$5),"-")) )) -> - | H36: =$N$4/$E$5 -> #DIV/0! | I36: =IF($B$2="Avaliados",H36-H36,N36*'Precificação'!$C$38) -> #DIV/0! | J36: =IF(I36>0,H36+I36,0) -> #DIV/0!
A37: academia b | C37: 25 | D37: =MINIFS('Variação'!I:I,'Variação'!B:B,B37) -> 0 | G37: =IF(N37="","-",IF(AND($B$2="Direta" , $B$4="N/A"),"Só Em Dinheiro",IF(AND($B$2="Avaliados",$B$4="Do Clube"),N37-(N37*20%)-($N$4/$E$5),IF(AND($B$2="Avaliados",$B$4="Fora do Clube"),N37-(N37*40%)-($N$4/$E$5),"-")) )) -> - | H37: =$N$4/$E$5 -> #DIV/0! | I37: =IF($B$2="Avaliados",H37-H37,N37*'Precificação'!$C$38) -> #DIV/0! | J37: =IF(I37>0,H37+I37,0) -> #DIV/0!
A38: short | C38: 20 | D38: =MINIFS('Variação'!I:I,'Variação'!B:B,B38) -> 0 | G38: =IF(N38="","-",IF(AND($B$2="Direta" , $B$4="N/A"),"Só Em Dinheiro",IF(AND($B$2="Avaliados",$B$4="Do Clube"),N38-(N38*20%)-($N$4/$E$5),IF(AND($B$2="Avaliados",$B$4="Fora do Clube"),N38-(N38*40%)-($N$4/$E$5),"-")) )) -> - | H38: =$N$4/$E$5 -> #DIV/0! | I38: =IF($B$2="Avaliados",H38-H38,N38*'Precificação'!$C$38) -> #DIV/0! | J38: =IF(I38>0,H38+I38,0) -> #DIV/0!
A39: short | C39: 20 | D39: =MINIFS('Variação'!I:I,'Variação'!B:B,B39) -> 0 | G39: =IF(N39="","-",IF(AND($B$2="Direta" , $B$4="N/A"),"Só Em Dinheiro",IF(AND($B$2="Avaliados",$B$4="Do Clube"),N39-(N39*20%)-($N$4/$E$5),IF(AND($B$2="Avaliados",$B$4="Fora do Clube"),N39-(N39*40%)-($N$4/$E$5),"-")) )) -> - | H39: =$N$4/$E$5 -> #DIV/0! | I39: =IF($B$2="Avaliados",H39-H39,N39*'Precificação'!$C$38) -> #DIV/0! | J39: =IF(I39>0,H39+I39,0) -> #DIV/0!
A40: saia | C40: 20 | D40: =MINIFS('Variação'!I:I,'Variação'!B:B,B40) -> 0 | G40: =IF(N40="","-",IF(AND($B$2="Direta" , $B$4="N/A"),"Só Em Dinheiro",IF(AND($B$2="Avaliados",$B$4="Do Clube"),N40-(N40*20%)-($N$4/$E$5),IF(AND($B$2="Avaliados",$B$4="Fora do Clube"),N40-(N40*40%)-($N$4/$E$5),"-")) )) -> - | H40: =$N$4/$E$5 -> #DIV/0! | I40: =IF($B$2="Avaliados",H40-H40,N40*'Precificação'!$C$38) -> #DIV/0! | J40: =IF(I40>0,H40+I40,0) -> #DIV/0!
...

Sheet Página20

Sheet Página19
A2: Código loja
A3: Código categoria
A4: Data cadastro
A5: Nome produto
A6: Código produto
A7: Imagem principal
A8: Imagem 2
A9: Imagem 3
A10: Imagem 4
A11: Preço venda
A12: Peso
A13: Frete
... A47: Nome categoria

Sheet Variação
A1: Código variação | B1: Código produto | C1: EAN | D1: Variação principal | E1: Valor variação principal | F1: Variação 2 | G1: Valor variação 2 | H1: Peso | I1: Preço venda | J1: Estoque | K1: Quantidade vendida | L1: Preço custo | M1: Inicio promoção | N1: Fim promoção | O1: Preço promoção | P1: Referência | Q1: Imagem | R1: Comprimento | S1: Largura | T1: Altura | U1: Imagens adicionais
A2: 9 | B2: 69 | C2: 7894443800029 | D2: COR | E2: Preto | F2: Tamanho | G2: 28 | H2: 500 | I2: 50 | J2: 0 | K2: 4 | L2: 35 | O2: 0 | P2: § | Q2: https://images.tcdn.com.br/img/img_prod/995386/melissa_mel_flox_69_variacao_9_2_d672c57421724e7aa4a142a0bc03133a.jpeg | U2: https://images.tcdn.com.br/img/img_prod/995386/melissa_mel_flox_69_variacao_9_2_d672c57421724e7aa4a142a0bc03133a.jpeg, https://images.tcdn.com.br/img/img_prod/995386/melissa_mel_flox_69_variacao_9_3_a51455984a0c38fca57fc915b246f156.jpeg, https://images.tcdn.com.br/img/img_prod/995386/melissa_mel_flox_69_variacao_9_4_952058f6bf4468804982d67b2ee98313.jpeg, https://images.tcdn.com.br/img/img_prod/995386/melissa_mel_flox_69_variacao_9_5_e24d430bf7b36da07458d2742b8485a5.jpeg, https://images.tcdn.com.br/img/img_prod/995386/melissa_mel_flox_69_variacao_9_6_040594a10798bdcf5b792526bdd8a677.jpeg
A3: 25 | B3: 125 | C3: 7894443800036 | D3: COR | E3: Preto | F3: Tamanho | G3: 19 | H3: 100 | I3: 70 | J3: 0 | K3: 1 | L3: 33.34 | O3: 0 | P3: § | Q3: https://images.tcdn.com.br/img/img_prod/995386/mini_melissa_papete_rider_125_variacao_25_3_40df20e587a9f77cb3ea0a7bfb0ee0b1.jpeg | R3: 25 | S3: 15 | T3: 10 | U3: https://images.tcdn.com.br/img/img_prod/995386/mini_melissa_papete_rider_125_variacao_25_3_40df20e587a9f77cb3ea0a7bfb0ee0b1.jpeg, https://images.tcdn.com.br/img/img_prod/995386/mini_melissa_papete_rider_125_variacao_25_4_e754b9fb81c3ca7399f5f58a1572f7f4.jpeg, https://images.tcdn.com.br/img/img_prod/995386/mini_melissa_papete_rider_125_variacao_25_5_51800343d5e3645a64b9ec0c6cb078c6.jpeg
A4: 43 | B4: 37 | C4: 7894443800043 | D4: COR | E4: Amarelo | H4: 500 | I4: 65 | J4: 0 | K4: 3 | L4: 45 | O4: 0 | P4: § | Q4: https://images.tcdn.com.br/img/img_prod/995386/my_first_mini_melissa_tricot_37_variacao_43_2_cbe154edf208981e12f8f0fb550fffce.jpeg | R4: 20 | S4: 12 | T4: 10 | U4: https://images.tcdn.com.br/img/img_prod/995386/my_first_mini_melissa_tricot_37_variacao_43_2_cbe154edf208981e12f8f0fb550fffce.jpeg, https://images.tcdn.com.br/img/img_prod/995386/my_first_mini_melissa_tricot_37_variacao_43_3_0e574f337355636a1f474f5752e9e64d.jpeg, https://images.tcdn.com.br/img/img_prod/995386/my_first_mini_melissa_tricot_37_variacao_43_4_64685628f9a28222e9ecaae6ba2d2705.jpeg, https://images.tcdn.com.br/img/img_prod/995386/my_first_mini_melissa_tricot_37_variacao_43_5_d539577edbd694096925efd565d11b29.jpeg
A5: 45 | B5: 37 | C5: 7894443800050 | D5: COR | E5: Vermelho | H5: 300 | I5: 65 | J5: 0 | K5: 4 | L5: 45 | O5: 0 | P5: § | Q5: https://images.tcdn.com.br/img/img_prod/995386/my_first_mini_melissa_tricot_37_variacao_45_2_680e063cfb915f645c15dd789cf88d8e.jpeg | R5: 25 | S5: 15 | T5: 10 | U5: https://images.tcdn.com.br/img/img_prod/995386/my_first_mini_melissa_tricot_37_variacao_45_2_680e063cfb915f645c15dd789cf88d8e.jpeg, https://images.tcdn.com.br/img/img_prod/995386/my_first_mini_melissa_tricot_37_variacao_45_3_224bb99bfd4a482cd44f168f5a230fbb.jpeg, https://images.tcdn.com.br/img/img_prod/995386/my_first_mini_melissa_tricot_37_variacao_45_4_64777c8aee15258778f83d312762434f.jpeg, https://images.tcdn.com.br/img/img_prod/995386/my_first_mini_melissa_tricot_37_variacao_45_5_341f2469cb2e710af8d10591dbd24ab1.jpeg
A6: 55 | B6: 139 | C6: 7894443800067 | D6: COR | E6: Rosa | F6: Tamanho | G6: 26/27 | H6: 100 | I6: 65 | J6: 0 | K6: 2 | L6: 40 | O6: 0 | P6: § | Q6: https://images.tcdn.com.br/img/img_prod/995386/mini_melissa_maggie_bear_139_variacao_55_2_765ad78f34c8a9fac3a09e7c9ea036bd.jpeg | R6: 25 | S6: 15 | T6: 10 | U6: https://images.tcdn.com.br/img/img_prod/995386/mini_melissa_maggie_bear_139_variacao_55_2_765ad78f34c8a9fac3a09e7c9ea036bd.jpeg, https://images.tcdn.com.br/img/img_prod/995386/mini_melissa_maggie_bear_139_variacao_55_3_946be4b1137d4accfbaccc6235172a12.jpeg, https://images.tcdn.com.br/img/img_prod/995386/mini_melissa_maggie_bear_139_variacao_55_4_e5f5580575dd2e37ce3749a2591af7f4.jpeg, https://images.tcdn.com.br/img/img_prod/995386/mini_melissa_maggie_bear_139_variacao_55_5_2bd3503a2fed9e00fb829462c85d0c5c.jpeg
A7: 73 | B7: 121 | C7: 7894443800074 | D7: COR | E7: Rosa Choque | F7: Tamanho | G7: 20/21 | I7: 60 | J7: 0 | K7: 4 | L7: 0 | O7: 0 | P7: § | Q7: https://images.tcdn.com.br/img/img_prod/995386/mini_melissa_sneaker_love_system_121_variacao_73_2_226c85d7ce35081e9dbc54ca41e000b3.jpeg | U7: https://images.tcdn.com.br/img/img_prod/995386/mini_melissa_sneaker_love_system_121_variacao_73_2_226c85d7ce35081e9dbc54ca41e000b3.jpeg, https://images.tcdn.com.br/img/img_prod/995386/mini_melissa_sneaker_love_system_121_variacao_73_3_efcd0f0f58dfd81b5f7e03f0e969c31c.jpeg, https://images.tcdn.com.br/img/img_prod/995386/mini_melissa_sneaker_love_system_121_variacao_73_4_eeb8f6669286502adf267fcccfb04154.jpeg, https://images.tcdn.com.br/img/img_prod/995386/mini_melissa_sneaker_love_system_121_variacao_73_5_fa28ac0672914a0e6d6c542f0eca580e.jpeg
A8: 79 | B8: 87 | C8: 7894443800081 | D8: COR | E8: Rosa Glitter | F8: Tamanho | G8: 20/21 | H8: 500 | I8: 85 | J8: 0 | K8: 3 | L8: 42.58 | M8: 44489 | N8: 44500 | O8: 60 | P8: § | Q8: https://images.tcdn.com.br/img/img_prod/995386/mini_melissa_possession_87_variacao_79_3_586ce9c9c3abcc517e70169393f47057.jpeg | R8: 25 | S8: 15 | T8: 10 | U8: https://images.tcdn.com.br/img/img_prod/995386/mini_melissa_possession_87_variacao_79_3_586ce9c9c3abcc517e70169393f47057.jpeg, https://images.tcdn.com.br/img/img_prod/995386/mini_melissa_possession_87_variacao_79_4_d32725398b013caab5a5efbd495c7b9a.jpeg, https://images.tcdn.com.br/img/img_prod/995386/mini_melissa_possession_87_variacao_79_5_e37704c83eeacea6be6d6061495663a1.jpeg
A9: 87 | B9: 159 | C9: 7894443800098 | D9: COR | E9: Preto | F9: Tamanho | G9: 17/18 | H9: 500 | I9: 50 | J9: 0 | K9: 1 | L9: 22.98 | O9: 0 | P9: 5 seminova | Q9: https://images.tcdn.com.br/img/img_prod/995386/mini_melissa_ultragirl_a_bela_e_a_fera_159_variacao_87_2_dcae212f43e2df1293844b720c2391d4.jpg | R9: 25 | S9: 15 | T9: 10 | U9: https://images.tcdn.com.br/img/img_prod/995386/mini_melissa_ultragirl_a_bela_e_a_fera_159_variacao_87_2_dcae212f43e2df1293844b720c2391d4.jpg, https://images.tcdn.com.br/img/img_prod/995386/mini_melissa_ultragirl_a_bela_e_a_fera_159_variacao_87_3_12a04e1c663c330aa2a6602a272b2282.jpg, https://images.tcdn.com.br/img/img_prod/995386/mini_melissa_ultragirl_a_bela_e_a_fera_159_variacao_87_4_a9132fc73b908172af2419faa611f325.jpg, https://images.tcdn.com.br/img/img_prod/995386/mini_melissa_ultragirl_a_bela_e_a_fera_159_variacao_87_5_09aafaf03e05c7428bd8bfd3d518e3eb.jpg, https://images.tcdn.com.br/img/img_prod/995386/mini_melissa_ultragirl_a_bela_e_a_fera_159_variacao_87_6_1f69b723a79c4711ceb6d7da40edc980.jpg
A10: 93 | B10: 121 | C10: 7894443800104 | D10: COR | E10: Azul escuro | F10: Tamanho | G10: 17/18 | H10: 500 | I10: 50 | J10: 0 | K10: 1 | L10: 22.98 | O10: 0 | P10: § | Q10: https://images.tcdn.com.br/img/img_prod/995386/mini_melissa_sneaker_love_system_121_variacao_93_2_12cc4e7df6f5f92fad327694340f5114.jpeg | R10: 25 | S10: 15 | T10: 10 | U10: https://images.tcdn.com.br/img/img_prod/995386/mini_melissa_sneaker_love_system_121_variacao_93_2_12cc4e7df6f5f92fad327694340f5114.jpeg, https://images.tcdn.com.br/img/img_prod/995386/mini_melissa_sneaker_love_system_121_variacao_93_3_95f94cbd1d724fe453571618f57011a9.jpeg, https://images.tcdn.com.br/img/img_prod/995386/mini_melissa_sneaker_love_system_121_variacao_93_4_93bcffdb9c0e99b38432a01bf85a78c2.jpeg, https://images.tcdn.com.br/img/img_prod/995386/mini_melissa_sneaker_love_system_121_variacao_93_5_0af925c3a68dff4c9e4e78694d1c100b.jpeg
A11: 95 | B11: 163 | C11: 7894443800111 | D11: COR | E11: Rosa | F11: Tamanho | G11: 23/24 | H11: 500 | I11: 55 | J11: 0 | K11: 4 | L11: 40.34 | O11: 0 | P11: § | Q11: https://images.tcdn.com.br/img/img_prod/995386/mini_melissa_mar_sandal_swett_dreams_163_variacao_95_2_7cec0f6a93b10c1d6f3fb0e577e84a74.jpeg | R11: 20 | S11: 15 | T11: 10 | U11: https://images.tcdn.com.br/img/img_prod/995386/mini_melissa_mar_sandal_swett_dreams_163_variacao_95_2_7cec0f6a93b10c1d6f3fb0e577e84a74.jpeg, https://images.tcdn.com.br/img/img_prod/995386/mini_melissa_mar_sandal_swett_dreams_163_variacao_95_3_a88942bd0602ff893417d01b2feeaa67.jpeg, https://images.tcdn.com.br/img/img_prod/995386/mini_melissa_mar_sandal_swett_dreams_163_variacao_95_4_128d5816ae2873547ca8428f5c6bcb4d.jpeg, https://images.tcdn.com.br/img/img_prod/995386/mini_melissa_mar_sandal_swett_dreams_163_variacao_95_5_53e8d938f79dead48859dc0a413d3a46.jpeg
A12: 101 | B12: 83 | C12: 7894443800128 | D12: COR | E12: Rosa Glitter | F12: Tamanho | G12: 22 | H12: 500 | I12: 55 | J12: 0 | K12: 2 | L12: 40.54 | O12: 0 | P12: § | Q12: https://images.tcdn.com.br/img/img_prod/995386/mini_melissa_ultragirl_pequena_sereia_83_variacao_101_2_554319e2700d4b5e16793d85df44e3b7.jpeg | R12: 25 | S12: 15 | T12: 10 | U12: https://images.tcdn.com.br/img/img_prod/995386/mini_melissa_ultragirl_pequena_sereia_83_variacao_101_2_554319e2700d4b5e16793d85df44e3b7.jpeg, https://images.tcdn.com.br/img/img_prod/995386/mini_melissa_ultragirl_pequena_sereia_83_variacao_101_3_aa37a0e2f05fa9e86234d50af17efe16.jpeg, https://images.tcdn.com.br/img/img_prod/995386/mini_melissa_ultragirl_pequena_sereia_83_variacao_101_4_aa37a0e2f05fa9e86234d50af17efe16.jpeg, https://images.tcdn.com.br/img/img_prod/995386/mini_melissa_ultragirl_pequena_sereia_83_variacao_101_5_64487e7bb05e57d1ada24cf24d474912.jpeg, https://images.tcdn.com.br/img/img_prod/995386/mini_melissa_ultragirl_pequena_sereia_83_variacao_101_6_d47e0963675769f75e198f7da15efe57.jpeg
A13: 105 | B13: 55 | C13: 7894443800135 | D13: COR | E13: Preto | F13: Tamanho | G13: 28 | H13: 100 | I13: 58 | J13: 0 | K13: 1 | L13: 30.23 | O13: 0 | P13: § | Q13: https://images.tcdn.com.br/img/img_prod/995386/mini_melissa_ultragirl_swett_iii_55_variacao_105_2_ab1271c7de339b77847f66edac8f60ac.jpeg | R13: 25 | S13: 15 | T13: 10 | U13: https://images.tcdn.com.br/img/img_prod/995386/mini_melissa_ultragirl_swett_iii_55_variacao_105_2_ab1271c7de339b77847f66edac8f60ac.jpeg, https://images.tcdn.com.br/img/img_prod/995386/mini_melissa_ultragirl_swett_iii_55_variacao_105_3_c93367d7994cd9888cb1c5deabbeaa8d.jpeg, https://images.tcdn.com.br/img/img_prod/995386/mini_melissa_ultragirl_swett_iii_55_variacao_105_4_9ad5c690189eaf4b28769ee212da8644.jpeg, https://images.tcdn.com.br/img/img_prod/995386/mini_melissa_ultragirl_swett_iii_55_variacao_105_5_8a0ce303b026d9ffe2fda4ecf8ea830b.jpeg, https://images.tcdn.com.br/img/img_prod/995386/mini_melissa_ultragirl_swett_iii_55_variacao_105_6_cf35ce7eb81866b00f14aa66a2486d1c.jpeg
A14: 107 | B14: 55 | C14: 7894443800142 | D14: COR | E14: Colorido Glitter | F14: Tamanho | G14: 19 | H14: 500 | I14: 55 | J14: 0 | K14: 1 | L14: 30.23 | O14: 0 | P14: § | Q14: https://images.tcdn.com.br/img/img_prod/995386/mini_melissa_ultragirl_swett_iii_55_variacao_107_2_6c77a42f29a84232f2a5f3ef17c27fcf.jpeg | R14: 25 | S14: 15 | T14: 10 | U14: https://images.tcdn.com.br/img/img_prod/995386/mini_melissa_ultragirl_swett_iii_55_variacao_107_2_6c77a42f29a84232f2a5f3ef17c27fcf.jpeg, https://images.tcdn.com.br/img/img_prod/995386/mini_melissa_ultragirl_swett_iii_55_variacao_107_3_4cf289f8855a42ee72fc76f7e0113651.jpeg, https://images.tcdn.com.br/img/img_prod/995386/mini_melissa_ultragirl_swett_iii_55_variacao_107_4_65e984e5eafb52fc5922d1ac51b53c1c.jpeg, https://images.tcdn.com.br/img/img_prod/995386/mini_melissa_ultragirl_swett_iii_55_variacao_107_5_9774e56e3fb4585a24f1e0a7f2e10d4a.jpeg, https://images.tcdn.com.br/img/img_prod/995386/mini_melissa_ultragirl_swett_iii_55_variacao_107_6_65e984e5eafb52fc5922d1ac51b53c1c.jpeg
A15: 119 | B15: 53 | C15: 7894443800159 | D15: COR | E15: Preto | F15: Tamanho | G15: 20/21 | H15: 300 | I15: 40 | J15: 0 | K15: 3 | L15: 38.53 | O15: 0 | P15: § | Q15: https://images.tcdn.com.br/img/img_prod/995386/mini_melissa_campana_zig_zag_53_variacao_119_2_b68e4acfe05c9b5cb195805b3c47ca7d.jpeg | R15: 25 | S15: 15 | T15: 10 | U15: https://images.tcdn.com.br/img/img_prod/995386/mini_melissa_campana_zig_zag_53_variacao_119_2_b68e4acfe05c9b5cb195805b3c47ca7d.jpeg, https://images.tcdn.com.br/img/img_prod/995386/mini_melissa_campana_zig_zag_53_variacao_119_3_5fe10dd790e004e6db299f273896c8ee.jpeg, https://images.tcdn.com.br/img/img_prod/995386/mini_melissa_campana_zig_zag_53_variacao_119_4_68cab83609eada1ee918b0fef591e806.jpeg, https://images.tcdn.com.br/img/img_prod/995386/mini_melissa_campana_zig_zag_53_variacao_119_5_4762e7a3f884e263d15b1e26ddce7c46.jpeg
A16: 125 | B16: 171 | C16: 7894443800166 | D16: COR | E16: Colorido Glitter | F16: Tamanho | G16: 28 | H16: 500 | I16: 80 | J16: 0 | K16: 2 | L16: 31.3 | O16: 0 | P16: § | Q16: https://images.tcdn.com.br/img/img_prod/995386/mini_melissa_street_sneaker_171_variacao_125_2_1049a1a4d1a45e92a12cd770e82ce767.jpeg | R16: 25 | S16: 15 | T16: 10 | U16: https://images.tcdn.com.br/img/img_prod/995386/mini_melissa_street_sneaker_171_variacao_125_2_1049a1a4d1a45e92a12cd770e82ce767.jpeg, https://images.tcdn.com.br/img/img_prod/995386/mini_melissa_street_sneaker_171_variacao_125_3_73bf74f56d793772c7d1238f0281afe9.jpeg, https://images.tcdn.com.br/img/img_prod/995386/mini_melissa_street_sneaker_171_variacao_125_4_5ba7628ae610e301c060298a49255997.jpeg
A17: 129 | B17: 113 | C17: 7894443800173 | D17: COR | E17: Vidro Azul | F17: Tamanho | G17: 23/24 | H17: 500 | I17: 55 | J17: 0 | K17: 1 | L17: 24.27 | O17: 0 | P17: § | Q17: https://images.tcdn.com.br/img/img_prod/995386/mini_melissa_possession_unicornio_113_variacao_129_2_90c73ebc3e25ee04a18394519beac97e.jpeg | R17: 25 | S17: 15 | T17: 10 | U17: https://images.tcdn.com.br/img/img_prod/995386/mini_melissa_possession_unicornio_113_variacao_129_2_90c73ebc3e25ee04a18394519beac97e.jpeg, https://images.tcdn.com.br/img/img_prod/995386/mini_melissa_possession_unicornio_113_variacao_129_3_f43195ecff8404dc39863c84641642c6.jpeg
A18: 139 | B18: 65 | C18: 7894443800180 | D18: COR | E18: Rosa | F18: Tamanho | G18: 28 | H18: 500 | I18: 80 | J18: 0 | K18: 2 | L18: 134 | O18: 0 | P18: § | Q18: https://images.tcdn.com.br/img/img_prod/995386/mini_melissa_street_mickey_and_friends_65_variacao_139_2_c351d7399374d45b7d00113cd4131731.jpeg | R18: 25 | S18: 15 | T18: 10 | U18: https://images.tcdn.com.br/img/img_prod/995386/mini_melissa_street_mickey_and_friends_65_variacao_139_2_c351d7399374d45b7d00113cd4131731.jpeg, https://images.tcdn.com.br/img/img_prod/995386/mini_melissa_street_mickey_and_friends_65_variacao_139_3_ec6cb2ba891c4b0843fcfcabc94be601.jpeg, https://images.tcdn.com.br/img/img_prod/995386/mini_melissa_street_mickey_and_friends_65_variacao_139_4_23095fccf603266fb629cc37061a4338.jpeg, https://images.tcdn.com.br/img/img_prod/995386/mini_melissa_street_mickey_and_friends_65_variacao_139_5_e732814a80cf82a0e992c8f2f652fca6.jpeg
A19: 147 | B19: 65 | C19: 7894443800197 | D19: COR | E19: Branco | F19: Tamanho | G19: 26/27 | H19: 500 | I19: 80 | J19: 0 | K19: 2 | L19: 134 | O19: 0 | P19: § | Q19: https://images.tcdn.com.br/img/img_prod/995386/mini_melissa_street_mickey_and_friends_65_variacao_147_2_a703e6bd62237ac874dea96c580b0b10.jpeg | R19: 25 | S19: 15 | T19: 10 | U19: https://images.tcdn.com.br/img/img_prod/995386/mini_melissa_street_mickey_and_friends_65_variacao_147_2_a703e6bd62237ac874dea96c580b0b10.jpeg, https://images.tcdn.com.br/img/img_prod/995386/mini_melissa_street_mickey_and_friends_65_variacao_147_3_4e866f06f4e4bc4cb154753d3325f840.jpeg, https://images.tcdn.com.br/img/img_prod/995386/mini_melissa_street_mickey_and_friends_65_variacao_147_4_313a04e1d203cb9e73ebc42892ec0d01.jpeg, https://images.tcdn.com.br/img/img_prod/995386/mini_melissa_street_mickey_and_friends_65_variacao_147_5_b110645ebcdf1649c0f66cda3270f772.jpeg
A20: 149 | B20: 173 | C20: 7894443800203 | D20: COR | E20: Azul escuro | F20: Tamanho | G20: 17/18 | H20: 500 | I20: 55 | J20: 0 | K20: 1 | L20: 32.49 | O20: 0 | P20: § | Q20: https://images.tcdn.com.br/img/img_prod/995386/mini_melissa_ultragirl_swett_dreams_173_variacao_149_2_c4af13482e780d2e1333dfbd13517468.jpeg | R20: 25 | S20: 15 | T20: 10 | U20: https://images.tcdn.com.br/img/img_prod/995386/mini_melissa_ultragirl_swett_dreams_173_variacao_149_2_c4af13482e780d2e1333dfbd13517468.jpeg, https://images.tcdn.com.br/img/img_prod/995386/mini_melissa_ultragirl_swett_dreams_173_variacao_149_3_6c16ae1dbe1697d8c1e5805bcffaa694.jpeg, https://images.tcdn.com.br/img/img_prod/995386/mini_melissa_ultragirl_swett_dreams_173_variacao_149_4_786051f481d076df80aff9906db85d6f.jpeg, https://images.tcdn.com.br/img/img_prod/995386/mini_melissa_ultragirl_swett_dreams_173_variacao_149_5_59c93d81a8212aaf7c3ad7adfd6d28f4.jpeg, https://images.tcdn.com.br/img/img_prod/995386/mini_melissa_ultragirl_swett_dreams_173_variacao_149_6_db3d734e9e753631dc59cc68ae066f48.jpeg
A21: 165 | B21: 183 | C21: 7894443800227 | D21: COR | E21: Azul | F21: Tamanho | G21: 26/27 | I21: 50 | J21: -1 | K21: 3 | L21: 25 | O21: 0 | P21: § | Q21: https://images.tcdn.com.br/img/img_prod/995386/mini_melissa_aranha_vivienne_westwood_183_variacao_165_2_efb883915eb0278877d3eb220a514e98.jpeg | U21: https://images.tcdn.com.br/img/img_prod/995386/mini_melissa_aranha_vivienne_westwood_183_variacao_165_2_efb883915eb0278877d3eb220a514e98.jpeg, https://images.tcdn.com.br/img/img_prod/995386/mini_melissa_aranha_vivienne_westwood_183_variacao_165_3_4bc2c977e75a1bcff4e1f20030ac83e7.jpeg, https://images.tcdn.com.br/img/img_prod/995386/mini_melissa_aranha_vivienne_westwood_183_variacao_165_4_785ee7b78a54089bc49ba7427bff188d.jpeg, https://images.tcdn.com.br/img/img_prod/995386/mini_melissa_aranha_vivienne_westwood_183_variacao_165_5_a0af77d3b9d016fca69ba45011c42f04.jpeg, https://images.tcdn.com.br/img/img_prod/995386/mini_melissa_aranha_vivienne_westwood_183_variacao_165_6_3f05f767294b3deef5e1818fcc024eba.jpeg
A22: 169 | B22: 185 | C22: 7894443800234 | D22: COR | E22: Preto | F22: Tamanho | G22: 33/34 | H22: 200 | I22: 50 | J22: 0 | K22: 1 | L22: 25 | O22: 0 | P22: § | Q22: https://images.tcdn.com.br/img/img_prod/995386/melissa_color_pop_malevola_185_variacao_169_2_70b0ef3483e383620088f9e7ffc71223.jpeg | R22: 25 | S22: 15 | T22: 10 | U22: https://images.tcdn.com.br/img/img_prod/995386/melissa_color_pop_malevola_185_variacao_169_2_70b0ef3483e383620088f9e7ffc71223.jpeg, https://images.tcdn.com.br/img/img_prod/995386/melissa_color_pop_malevola_185_variacao_169_3_fbc013e20aca5b1c608910d9e0a40def.jpeg, https://images.tcdn.com.br/img/img_prod/995386/melissa_color_pop_malevola_185_variacao_169_4_655f1e065a9f5c26e05d9f1fd8c08c98.jpeg, https://images.tcdn.com.br/img/img_prod/995386/melissa_color_pop_malevola_185_variacao_169_5_d640d745040ae9e2623d1f844630f3a3.jpeg
A23: 171 | B23: 69 | C23: 7894443800241 | D23: COR | E23: Preto | F23: Tamanho | G23: 29 | H23: 300 | I23: 75 | J23: 0 | K23: 4 | L23: 30.5 | O23: 0 | P23: § | Q23: https://images.tcdn.com.br/img/img_prod/995386/melissa_mel_flox_69_variacao_171_2_a24832e9de741b7d1424d66140eafd74.jpg | R23: 25 | S23: 15 | T23: 10 | U23: https://images.tcdn.com.br/img/img_prod/995386/melissa_mel_flox_69_variacao_171_2_a24832e9de741b7d1424d66140eafd74.jpg, https://images.tcdn.com.br/img/img_prod/995386/melissa_mel_flox_69_variacao_171_3_8526257a5f3117af9c1b67b3f21e27ca.jpg, https://images.tcdn.com.br/img/img_prod/995386/melissa_mel_flox_69_variacao_171_4_4646551be1bf893fb49ab1dcebc7303c.jpg, https://images.tcdn.com.br/img/img_prod/995386/melissa_mel_flox_69_variacao_171_5_2b86065e4cb8d2dbbac214c0597bd40a.jpg, https://images.tcdn.com.br/img/img_prod/995386/melissa_mel_flox_69_variacao_171_6_b25c1348360929c425822018ec30a5bb.jpg
A24: 175 | B24: 187 | C24: 7894443800258 | D24: COR | E24: Rosa Choque | F24: Tamanho | G24: 17/18 | I24: 60 | J24: 0 | K24: 2 | L24: 40 | O24: 0 | P24: § | Q24: https://images.tcdn.com.br/img/img_prod/995386/mini_melissa_sneaker_be_187_variacao_175_2_a7e9c2b7e7e7653a39d9c2ec476a7431.jpeg | U24: https://images.tcdn.com.br/img/img_prod/995386/mini_melissa_sneaker_be_187_variacao_175_2_a7e9c2b7e7e7653a39d9c2ec476a7431.jpeg, https://images.tcdn.com.br/img/img_prod/995386/mini_melissa_sneaker_be_187_variacao_175_3_b507ae6f4708aa2f54a1d257fbd9c717.jpeg, https://images.tcdn.com.br/img/img_prod/995386/mini_melissa_sneaker_be_187_variacao_175_4_bd68beeaec7a92314541a2dff2785f49.jpeg, https://images.tcdn.com.br/img/img_prod/995386/mini_melissa_sneaker_be_187_variacao_175_5_f4933c408161f4519c96e58bc167c0b5.jpeg, https://images.tcdn.com.br/img/img_prod/995386/mini_melissa_sneaker_be_187_variacao_175_6_408dda468aff008027d5c68c4ed1e4f6.jpeg
A25: 179 | B25: 189 | C25: 7894443800265 | D25: COR | E25: Perola | F25: Tamanho | G25: 22 | H25: 500 | I25: 55 | J25: 0 | K25: 1 | L25: 31.71 | O25: 0 | P25: § | Q25: https://images.tcdn.com.br/img/img_prod/995386/mini_melissa_mar_sandal_189_variacao_179_2_a201e556bc1f10be314e4ef4c528856a.jpeg | R25: 25 | S25: 15 | T25: 10 | U25: https://images.tcdn.com.br/img/img_prod/995386/mini_melissa_mar_sandal_189_variacao_179_2_a201e556bc1f10be314e4ef4c528856a.jpeg, https://images.tcdn.com.br/img/img_prod/995386/mini_melissa_mar_sandal_189_variacao_179_3_55b156bcb265220ff709467845d3da91.jpeg, https://images.tcdn.com.br/img/img_prod/995386/mini_melissa_mar_sandal_189_variacao_179_4_55b156bcb265220ff709467845d3da91.jpeg, https://images.tcdn.com.br/img/img_prod/995386/mini_melissa_mar_sandal_189_variacao_179_5_658af3a88d48dc213ab546803bf894c7.jpeg, https://images.tcdn.com.br/img/img_prod/995386/mini_melissa_mar_sandal_189_variacao_179_6_49ea6faa4468fbac4fb9a7d543f3600b.jpeg
A26: 205 | B26: 125 | C26: 7894443800272 | D26: COR | E26: Rosa Glitter | F26: Tamanho | G26: 17/18 | H26: 500 | I26: 60 | J26: 0 | K26: 3 | L26: 70 | O26: 0 | P26: usada | Q26: https://images.tcdn.com.br/img/img_prod/995386/mini_melissa_papete_rider_125_variacao_205_3_7d8cf5f5b956c5c9d7b36396b1b0aad8.jpg | R26: 25 | S26: 15 | T26: 10 | U26: https://images.tcdn.com.br/img/img_prod/995386/mini_melissa_papete_rider_125_variacao_205_3_7d8cf5f5b956c5c9d7b36396b1b0aad8.jpg, https://images.tcdn.com.br/img/img_prod/995386/mini_melissa_papete_rider_125_variacao_205_4_271237aac9484b0cbe6d4b73f5ff6c19.jpg
A27: 207 | B27: 193 | C27: 7894443800289 | D27: COR | E27: Rosa Glitter | F27: Tamanho | G27: 19 | H27: 500 | I27: 55 | J27: 0 | K27: 2 | L27: 70 | O27: 0 | P27: § | Q27: https://images.tcdn.com.br/img/img_prod/995386/mini_melissa_wide_sandal_193_variacao_207_2_4a1322d697a4dfe7524bb91a626c616e.jpeg | R27: 25 | S27: 15 | T27: 10 | U27: https://images.tcdn.com.br/img/img_prod/995386/mini_melissa_wide_sandal_193_variacao_207_2_4a1322d697a4dfe7524bb91a626c616e.jpeg, https://images.tcdn.com.br/img/img_prod/995386/mini_melissa_wide_sandal_193_variacao_207_3_35c0937911f7634ce351e7f64dfd7c81.jpeg, https://images.tcdn.com.br/img/img_prod/995386/mini_melissa_wide_sandal_193_variacao_207_4_1204e09e4b5f2c128f2361b77605bfbf.jpeg, https://images.tcdn.com.br/img/img_prod/995386/mini_melissa_wide_sandal_193_variacao_207_5_50afbc3933234dd081b1fb107a11ea74.jpeg
A28: 209 | B28: 171 | C28: 7894443800296 | D28: COR | E28: Rosa Glitter | F28: Tamanho | G28: 20/21 | H28: 500 | I28: 70 | J28: 0 | K28: 1 | L28: 45 | O28: 0 | P28: § | Q28: https://images.tcdn.com.br/img/img_prod/995386/mini_melissa_street_sneaker_171_variacao_209_2_6cddadefdba8b63b573d4575f1eaa8e3.jpeg | R28: 25 | S28: 15 | T28: 10 | U28: https://images.tcdn.com.br/img/img_prod/995386/mini_melissa_street_sneaker_171_variacao_209_2_6cddadefdba8b63b573d4575f1eaa8e3.jpeg, https://images.tcdn.com.br/img/img_prod/995386/mini_melissa_street_sneaker_171_variacao_209_3_08e1bcd2a133a962196462823e908ad7.jpeg
A29: 225 | B29: 118 | C29: 7894443800302 | D29: COR | E29: Preto | F29: Tamanho | G29: 22 | H29: 500 | I29: 50 | J29: 0 | K29: 1 | L29: 34 | O29: 0 | P29: § | Q29: https://images.tcdn.com.br/img/img_prod/995386/mini_melissa_ultragirl_bamby_118_variacao_225_2_8643077d7874dec5f839f9e68edd2e50.jpeg | R29: 25 | S29: 15 | T29: 10 | U29: https://images.tcdn.com.br/img/img_prod/995386/mini_melissa_ultragirl_bamby_118_variacao_225_2_8643077d7874dec5f839f9e68edd2e50.jpeg, https://images.tcdn.com.br/img/img_prod/995386/mini_melissa_ultragirl_bamby_118_variacao_225_3_97e6e5dda2284e0cc70938afa8d74393.jpeg, https://images.tcdn.com.br/img/img_prod/995386/mini_melissa_ultragirl_bamby_118_variacao_225_4_fac28105f9bdb117f635fca407b9d77e.jpeg, https://images.tcdn.com.br/img/img_prod/995386/mini_melissa_ultragirl_bamby_118_variacao_225_5_c2ca91c47a5d1cad5c34d17fca10f692.jpeg, https://images.tcdn.com.br/img/img_prod/995386/mini_melissa_ultragirl_bamby_118_variacao_225_6_aa1dde6aceb8ef5b61fc6876306e7e94.jpeg
A30: 233 | B30: 53 | C30: 7894443800319 | D30: COR | E30: Prata | F30: Tamanho | G30: 25 | I30: 50 | J30: 0 | K30: 2 | L30: 30 | O30: 0 | P30: 54 usada | Q30: https://images.tcdn.com.br/img/img_prod/995386/mini_melissa_campana_zig_zag_53_variacao_233_2_26db1f9188a74b6e5ebe1e37bd697be5.jpg | U30: https://images.tcdn.com.br/img/img_prod/995386/mini_melissa_campana_zig_zag_53_variacao_233_2_26db1f9188a74b6e5ebe1e37bd697be5.jpg, https://images.tcdn.com.br/img/img_prod/995386/mini_melissa_campana_zig_zag_53_variacao_233_3_ab50d2bac446fb028d5d208715a4cbb9.jpg, https://images.tcdn.com.br/img/img_prod/995386/mini_melissa_campana_zig_zag_53_variacao_233_4_5c995583d697e3725a3ca5e4c4c42561.jpg, https://images.tcdn.com.br/img/img_prod/995386/mini_melissa_campana_zig_zag_53_variacao_233_5_5614a89124f5f4e47846add10cded541.jpg, https://images.tcdn.com.br/img/img_prod/995386/mini_melissa_campana_zig_zag_53_variacao_233_6_add23ed693585043652da7af67abf806.jpg
A31: 237 | B31: 103 | C31: 7894443800326 | D31: COR | E31: Amarelo | F31: Tamanho | G31: 22 | I31: 65 | J31: 0 | K31: 6 | L31: 29.9 | O31: 0 | P31: § | Q31: https://images.tcdn.com.br/img/img_prod/995386/mini_melissa_jump_frutland_abacaxi_morango_melancia_abacate_103_variacao_237_2_3453d47d431eb92dd83380b732df1b80.jpeg | U31: https://images.tcdn.com.br/img/img_prod/995386/mini_melissa_jump_frutland_abacaxi_morango_melancia_abacate_103_variacao_237_2_3453d47d431eb92dd83380b732df1b80.jpeg, https://images.tcdn.com.br/img/img_prod/995386/mini_melissa_jump_frutland_abacaxi_morango_melancia_abacate_103_variacao_237_3_5be27f555817f45f6d22d048668839c7.jpeg, https://images.tcdn.com.br/img/img_prod/995386/mini_melissa_jump_frutland_abacaxi_morango_melancia_abacate_103_variacao_237_4_a7bebf3b160c9e8d42d2cb86625d574c.jpeg, https://images.tcdn.com.br/img/img_prod/995386/mini_melissa_jump_frutland_abacaxi_morango_melancia_abacate_103_variacao_237_5_b8263fed31f254c149c46e45139b3c53.jpeg, https://images.tcdn.com.br/img/img_prod/995386/mini_melissa_jump_frutland_abacaxi_morango_melancia_abacate_103_variacao_237_6_30863841591c48515ab2121a615a8d23.jpeg
A32: 239 | B32: 189 | C32: 7894443800333 | D32: COR | E32: Dourado Glitter | F32: Tamanho | G32: 17/18 | I32: 55 | J32: 0 | K32: 5 | L32: 30 | O32: 0 | P32: nova | Q32: https://images.tcdn.com.br/img/img_prod/995386/mini_melissa_mar_sandal_189_variacao_239_2_5427b36d70ed527e298065c978d46b49.jpeg | U32: https://images.tcdn.com.br/img/img_prod/995386/mini_melissa_mar_sandal_189_variacao_239_2_5427b36d70ed527e298065c978d46b49.jpeg, https://images.tcdn.com.br/img/img_prod/995386/mini_melissa_mar_sandal_189_variacao_239_3_875e2c000d2273add3618e839ca4ae66.jpeg, https://images.tcdn.com.br/img/img_prod/995386/mini_melissa_mar_sandal_189_variacao_239_4_151ded783ea94d5ab25ae337e460d850.jpeg, https://images.tcdn.com.br/img/img_prod/995386/mini_melissa_mar_sandal_189_variacao_239_5_5e7d0b34bf9d2954acb6f66882d8f2f1.jpeg, https://images.tcdn.com.br/img/img_prod/995386/mini_melissa_mar_sandal_189_variacao_239_6_3fa9e4e395c71360d5e2ec0171caef3b.jpg
A33: 245 | B33: 72 | C33: 7894443800340 | D33: COR | E33: Preto | F33: Tamanho | G33: 17/18 | I33: 55 | J33: 0 | K33: 1 | L33: 25 | O33: 0 | P33: § | Q33: https://images.tcdn.com.br/img/img_prod/995386/mini_melissa_possession_turma_do_pudim_72_variacao_245_3_dcc0a58a4367c7a73c3ac13ac208241d.jpeg | U33: https://images.tcdn.com.br/img/img_prod/995386/mini_melissa_possession_turma_do_pudim_72_variacao_245_3_dcc0a58a4367c7a73c3ac13ac208241d.jpeg
A34: 255 | B34: 201 | C34: 7894443800357 | D34: COR | E34: Vermelho | F34: Tamanho | G34: 17/18 | H34: 300 | I34: 65 | J34: 0 | K34: 2 | L34: 40 | O34: 0 | P34: § | Q34: https://images.tcdn.com.br/img/img_prod/995386/mini_melissa_snacker_be_ad_hello_kitty_201_variacao_255_2_fe1186951c2bfa8d79d1d7c98023eb79.jpeg | R34: 25 | S34: 15 | T34: 10 | U34: https://images.tcdn.com.br/img/img_prod/995386/mini_melissa_snacker_be_ad_hello_kitty_201_variacao_255_2_fe1186951c2bfa8d79d1d7c98023eb79.jpeg, https://images.tcdn.com.br/img/img_prod/995386/mini_melissa_snacker_be_ad_hello_kitty_201_variacao_255_3_ad199165a50591f8ef0bd35e0b08877e.jpeg, https://images.tcdn.com.br/img/img_prod/995386/mini_melissa_snacker_be_ad_hello_kitty_201_variacao_255_4_59f4f3be726d989291cbae7c4c27db52.jpeg, https://images.tcdn.com.br/img/img_prod/995386/mini_melissa_snacker_be_ad_hello_kitty_201_variacao_255_5_23cc6419185071459bea4a7e910b4762.jpeg, https://images.tcdn.com.br/img/img_prod/995386/mini_melissa_snacker_be_ad_hello_kitty_201_variacao_255_6_63ca377c0eae09fc7289a8e97eded738.jpeg, https://images.tcdn.com.br/img/img_prod/995386/mini_melissa_snacker_be_ad_hello_kitty_201_variacao_255_7_efe14ce9a2b1b5f83b8bfe90f4ab0330.jpeg
A35: 267 | B35: 39 | C35: 7894443800364 | D35: COR | E35: Amarelo | F35: Tamanho | G35: 17/18 | H35: 100 | I35: 60 | J35: 0 | K35: 1 | L35: 50 | O35: 0 | P35: § | Q35: https://images.tcdn.com.br/img/img_prod/995386/galocha_mini_melissa_sugar_rain_fabula_39_variacao_267_2_63dfdb05a719ae22de0cb26488aaafd4.jpeg | R35: 25 | S35: 15 | T35: 10 | U35: https://images.tcdn.com.br/img/img_prod/995386/galocha_mini_melissa_sugar_rain_fabula_39_variacao_267_2_63dfdb05a719ae22de0cb26488aaafd4.jpeg, https://images.tcdn.com.br/img/img_prod/995386/galocha_mini_melissa_sugar_rain_fabula_39_variacao_267_3_c61bf270f966673d2481535d2ba40e65.jpeg, https://images.tcdn.com.br/img/img_prod/995386/galocha_mini_melissa_sugar_rain_fabula_39_variacao_267_4_01462d8b875dcef981ec42d40f7079fe.jpeg, https://images.tcdn.com.br/img/img_prod/995386/galocha_mini_melissa_sugar_rain_fabula_39_variacao_267_5_40122db97ee280b12dfd358375270aac.jpeg, https://images.tcdn.com.br/img/img_prod/995386/galocha_mini_melissa_sugar_rain_fabula_39_variacao_267_6_2698a9d13be63402f87061a3e832e3f2.jpeg
A36: 269 | B36: 58 | C36: 7894443800371 | D36: COR | E36: Caramelo | F36: Tamanho | G36: 17/18 | H36: 500 | I36: 80 | J36: 0 | K36: 1 | L36: 44.71 | O36: 0 | P36: § | Q36: https://images.tcdn.com.br/img/img_prod/995386/mini_melissa_sugar_boot_winter_58_variacao_269_2_e6c92ebd223a7c62bfe817c46da13914.jpeg | R36: 25 | S36: 15 | T36: 10 | U36: https://images.tcdn.com.br/img/img_prod/995386/mini_melissa_sugar_boot_winter_58_variacao_269_2_e6c92ebd223a7c62bfe817c46da13914.jpeg, https://images.tcdn.com.br/img/img_prod/995386/mini_melissa_sugar_boot_winter_58_variacao_269_3_6f833007a020a198509aeed554f55584.jpeg, https://images.tcdn.com.br/img/img_prod/995386/mini_melissa_sugar_boot_winter_58_variacao_269_4_e72fe7a11c2805ab3733ecfcfa385021.jpeg, https://images.tcdn.com.br/img/img_prod/995386/mini_melissa_sugar_boot_winter_58_variacao_269_5_0591d879013a77dfbcfc9000a488cf89.jpeg
A37: 271 | B37: 203 | C37: 7894443800388 | D37: COR | E37: Lilás | F37: Tamanho | G37: 20/21 | H37: 500 | I37: 60 | J37: 0 | K37: 3 | L37: 44.71 | O37: 0 | P37: § | Q37: https://images.tcdn.com.br/img/img_prod/995386/mini_melissa_sneaker_be_ad_raibow_203_variacao_271_2_b35b6a9f4a078f319c43bc18e256e33c.jpeg | R37: 25 | S37: 15 | T37: 10 | U37: https://images.tcdn.com.br/img/img_prod/995386/mini_melissa_sneaker_be_ad_raibow_203_variacao_271_2_b35b6a9f4a078f319c43bc18e256e33c.jpeg, https://images.tcdn.com.br/img/img_prod/995386/mini_melissa_sneaker_be_ad_raibow_203_variacao_271_3_a62d7c94b74b4d6d99aca025177c228e.jpeg, https://images.tcdn.com.br/img/img_prod/995386/mini_melissa_sneaker_be_ad_raibow_203_variacao_271_4_50151578646175a010c907bb40b4a371.jpeg, https://images.tcdn.com.br/img/img_prod/995386/mini_melissa_sneaker_be_ad_raibow_203_variacao_271_5_4f6d1cb34b89201aa13b6e11e5a2907c.jpeg
A38: 277 | B38: 205 | C38: 7894443800395 | D38: COR | E38: Cinza | F38: Tamanho | G38: 17/18 | H38: 500 | I38: 60 | J38: 0 | K38: 1 | L38: 0 | O38: 0 | P38: § | Q38: https://images.tcdn.com.br/img/img_prod/995386/mini_melissa_ultragirl_animal_lovers_gata_205_variacao_277_2_6c318377510309443ece3177711ae075.jpeg | R38: 25 | S38: 15 | T38: 10 | U38: https://images.tcdn.com.br/img/img_prod/995386/mini_melissa_ultragirl_animal_lovers_gata_205_variacao_277_2_6c318377510309443ece3177711ae075.jpeg
A39: 281 | B39: 207 | C39: 7894443800401 | D39: COR | E39: marrom | F39: Tamanho | G39: 20/21 | H39: 100 | I39: 55 | J39: 0 | K39: 1 | L39: 21.08 | O39: 0 | P39: § | Q39: https://images.tcdn.com.br/img/img_prod/995386/mini_melissa_triple_bowl_207_variacao_281_2_e08f226ed3e9ceff0f2033f617fcadb2.jpeg | R39: 25 | S39: 15 | T39: 10 | U39: https://images.tcdn.com.br/img/img_prod/995386/mini_melissa_triple_bowl_207_variacao_281_2_e08f226ed3e9ceff0f2033f617fcadb2.jpeg, https://images.tcdn.com.br/img/img_prod/995386/mini_melissa_triple_bowl_207_variacao_281_3_bf294254a3262713d0dd1420c83a08ad.jpeg, https://images.tcdn.com.br/img/img_prod/995386/mini_melissa_triple_bowl_207_variacao_281_4_6cbf202219b7f943a7bdf05f571ca69f.jpeg, https://images.tcdn.com.br/img/img_prod/995386/mini_melissa_triple_bowl_207_variacao_281_5_0da9c5a2033ae6ce6e6f1786d5b9a8ae.jpeg
A40: 291 | B40: 111 | C40: 7894443800418 | D40: COR | E40: Rosa Glitter | F40: Tamanho | G40: 19 | I40: 55 | J40: 0 | K40: 0 | L40: 27.1 | O40: 0 | P40: § | Q40: https://images.tcdn.com.br/img/img_prod/995386/mini_melissa_ultragirl_unicornio_111_variacao_291_2_e640afd02d596b45543d3582ef955c77.jpeg | U40: https://images.tcdn.com.br/img/img_prod/995386/mini_melissa_ultragirl_unicornio_111_variacao_291_2_e640afd02d596b45543d3582ef955c77.jpeg, https://images.tcdn.com.br/img/img_prod/995386/mini_melissa_ultragirl_unicornio_111_variacao_291_3_705bfc3ca4cc38b8f52d765dc4e13f9a.jpeg, https://images.tcdn.com.br/img/img_prod/995386/mini_melissa_ultragirl_unicornio_111_variacao_291_4_1b87962f8098152baf906ae2110e2510.jpeg, https://images.tcdn.com.br/img/img_prod/995386/mini_melissa_ultragirl_unicornio_111_variacao_291_5_fb8daa6722c01cf0d1f1538a529d2efa.jpeg
...

Sheet Produtos
B1: Código loja | C1: Código categoria | D1: Data cadastro | E1: Nome produto | F1: Código produto | G1: Imagem principal | H1: Imagem 2 | I1: Imagem 3 | J1: Imagem 4 | K1: Preço venda | L1: Peso | M1: Frete | N1: Estoque atual | O1: Estoque mínimo | P1: Disponível | Q1: Inicio promoção | R1: Fim promoção | S1: Preço promoção | T1: Selo destaque | U1: Selo lançamento | V1: Selo adicional | W1: Quantidade vendida | X1: Marca | Y1: Modelo | Z1: Referência | AA1: EAN | AB1: Garantia | AC1: Tamanho | AD1: Cor | AE1: Preço de custo | AF1: Preço de custo em dólar | AG1: Disponibilidade | AH1: Itens inclusos | AI1: Mensagem adicional | AJ1: Comprimento | AK1: Largura | AL1: Altura | AM1: Data de ativação | AN1: Data de desativação | AO1: SEO Título | AP1: SEO descrição simplificada | AQ1: SEO palavra chave | AR1: Características | AS1: Endereço do Produto (URL Tray) | AT1: Imagens adicionais | AU1: Nome categoria
B2: 995386 | C2: 161 | D2: 44502 | E2: Mini Melissa Aranha Minnie | F2: 21 | G2: https://images.tcdn.com.br/img/img_prod/995386/mini_melissa_aranha_minnie_21_1_55ce6e102664f8e1284917e27e071023.jpeg | H2: https://images.tcdn.com.br/img/img_prod/995386/mini_melissa_aranha_minnie_21_2_48aa7c1f52c28c25734077cd130b3deb.jpg | I2: https://images.tcdn.com.br/img/img_prod/995386/mini_melissa_aranha_minnie_21_3_1680907f4c52ef26163a7003238e5e1b.jpg | K2: 0.00 | L2: 100 | M2: 0.00 | N2: -1 | O2: 0 | P2: Não | S2: 0.00 | T2: Não | U2: Não | V2: Não | W2: 7 | X2: Melissa | Y2: ARANHA | Z2: V21P104 | AA2: 21 | AB2: 7 dias após o recebimento do produto | AE2: 0.00 | AF2: 0.00 | AG2: Imediata | AJ2: 25 | AK2: 15 | AL2: 10 | AM2: 45201 | AN2: 45205 | AP2: Melissas novas, seminovas e usadas. Em ótimas condições de conservação. Todas higienizadas.Moda circular sustentável!Porque uma melissa bem cuidada é para sempre!? | AS2: https://www.minhamania.net/mini-melissa-aranha-minnie | AU2: Infantil
B3: 995386 | C3: 161 | D3: 44310 | E3: My First Mini Melissa Tricot | F3: 37 | G3: https://images.tcdn.com.br/img/img_prod/995386/my_first_mini_melissa_tricot_37_2_f6400ccfc718e2a01776ad5a31dba06f.jpeg | H3: https://images.tcdn.com.br/img/img_prod/995386/my_first_mini_melissa_tricot_37_2_20046460b02dc4e6c316db6b87a51b3c.jpeg | I3: https://images.tcdn.com.br/img/img_prod/995386/my_first_mini_melissa_tricot_37_1_219c3c171b931444319cb9ddf4124758.jpeg | K3: 65.00 | L3: 83 | M3: 0.00 | N3: 0 | O3: 0 | P3: Não | S3: 0.00 | T3: Não | U3: Não | V3: Não | W3: 7 | X3: Melissa | Y3: MY FIRST | AA3: 37 | AB3: 7 dias após o recebimento do produto | AE3: 45.00 | AF3: 0.00 | AG3: Imediata | AJ3: 10 | AK3: 5 | AL3: 3 | AM3: 44695 | AN3: 44902 | AP3: Melissas novas, seminovas e usadas. Em ótimas condições de conservação. Todas higienizadas.Moda circular sustentável!Porque uma melissa bem cuidada é para sempre!? | AS3: https://www.minhamania.net/mini-melissa/the-first-minha-primeira-melissa-tricot | AU3: Infantil
B4: 995386 | C4: 161 | D4: 44311 | E4: Galocha Mini Melissa Sugar Rain Fabula | F4: 39 | G4: https://images.tcdn.com.br/img/img_prod/995386/galocha_mini_melissa_sugar_rain_fabula_39_1_e95fd447cdd4fc6ef05167d635ac0b2e.png | K4: 50.00 | L4: 500 | M4: 0.00 | N4: 0 | O4: 0 | P4: Não | S4: 0.00 | T4: Não | U4: Não | V4: Não | W4: 2 | X4: Melissa | Z4: P39 | AA4: 39 | AB4: 7 dias após o recebimento do produto | AE4: 50.00 | AF4: 0.00 | AG4: Imediata | AJ4: 15 | AK4: 10 | AL4: 8 | AM4: 44618 | AN4: 44618 | AP4: Melissas novas, seminovas e usadas. Em ótimas condições de conservação. Todas higienizadas.Moda circular sustentável!Porque uma melissa bem cuidada é para sempre!? | AS4: https://www.minhamania.net/mini-melissa/galocha-mini-melissa-sugar-rain-fabula | AU4: Infantil
B5: 995386 | C5: 161 | D5: 44311 | E5: Mini Melissa Furadinha Babouche | F5: 41 | G5: https://images.tcdn.com.br/img/img_prod/995386/mini_melissa_furadinha_babouche_41_1_9a0685cdfaff42b43393106861b15cb8.jpeg | H5: https://images.tcdn.com.br/img/img_prod/995386/mini_melissa_furadinha_babouche_41_2_db44246f1d529264a804c205f9a502f0.jpeg | I5: https://images.tcdn.com.br/img/img_prod/995386/mini_melissa_furadinha_babouche_41_3_dbe01477538dd92f7f63f5967159d186.jpeg | K5: 55.00 | L5: 500 | M5: 0.00 | N5: 0 | O5: 0 | P5: Não | S5: 0.00 | T5: Não | U5: Não | V5: Não | W5: 25 | X5: Melissa | Y5: BABOUCHE | Z5: P41 | AA5: 41 | AE5: 0.00 | AF5: 0.00 | AJ5: 0 | AK5: 0 | AL5: 0 | AM5: 44850 | AN5: 44887 | AP5: Melissas novas, seminovas e usadas. Em ótimas condições de conservação. Todas higienizadas.Moda circular sustentável!Porque uma melissa bem cuidada é para sempre!? | AS5: https://www.minhamania.net/mini-melissa/mini-melissa-furadinha-babouche | AU5: Infantil
B6: 995386 | C6: 161 | D6: 44311 | E6: Mini Melissa Aranha + Fabula | F6: 43 | G6: https://images.tcdn.com.br/img/img_prod/995386/mini_melissa_aranha_fabula_43_1_e13b4cd0ec9fb053f93bfef668661a68.jpeg | K6: 45.00 | L6: 500 | M6: 0.00 | N6: 0 | O6: 0 | P6: Não | S6: 0.00 | T6: Não | U6: Não | V6: Não | W6: 2 | X6: Melissa | Z6: V43P37 | AA6: 43 | AB6: 7 dias após o recebimento do produto | AE6: 0.00 | AF6: 0.00 | AG6: Imediata | AJ6: 25 | AK6: 15 | AL6: 10 | AM6: 44727 | AN6: 44900 | AP6: Melissas novas, seminovas e usadas. Em ótimas condições de conservação. Todas higienizadas.Moda circular sustentável!Porque uma melissa bem cuidada é para sempre!? | AS6: https://www.minhamania.net/mini-melissa/mini-melissa-aranha-fabula | AU6: Infantil
B7: 995386 | C7: 161 | D7: 44316 | E7: Mini Melissa Furadinha Frutas | F7: 47 | G7: https://images.tcdn.com.br/img/img_prod/995386/mini_melissa_furadinha_frutas_47_1_1dca43ce9a507d4c1fee1cc570f1a4cc.jpeg | H7: https://images.tcdn.com.br/img/img_prod/995386/mini_melissa_furadinha_frutas_47_1_b168026b5d0e04f36f58e0f02fa70a5c.jpeg | I7: https://images.tcdn.com.br/img/img_prod/995386/mini_melissa_furadinha_frutas_47_2_701380c25c0d8f02b02f094e194df760.jpeg | J7: https://images.tcdn.com.br/img/img_prod/995386/mini_melissa_furadinha_frutas_47_5_dc28e296e8155415f04dc2e1d1b2dc2e.jpeg | K7: 40.00 | L7: 500 | M7: 0.00 | N7: 0 | O7: 0 | P7: Não | S7: 0.00 | T7: Não | U7: Não | V7: Não | W7: 17 | X7: Melissa | Z7: P47 | AA7: 47 | AE7: 29.77 | AF7: 0.00 | AG7: Imediata | AJ7: 20 | AK7: 15 | AL7: 10 | AM7: 45159 | AN7: 45355 | AP7: Melissas novas, seminovas e usadas. Em ótimas condições de conservação. Todas higienizadas.Moda circular sustentável!Porque uma melissa bem cuidada é para sempre!? | AS7: https://www.minhamania.net/mini-melissa/mini-melissa-furadinha-cereja | AT7: https://images.tcdn.com.br/img/img_prod/995386/mini_melissa_furadinha_frutas_47_5_0eb12176f57643579a0fac59c0bfa254.jpg, https://images.tcdn.com.br/img/img_prod/995386/mini_melissa_furadinha_frutas_47_6_611036c36dde990f73879a93084e9636.jpg | AU7: Infantil
B8: 995386 | C8: 161 | D8: 44316 | E8: Mini Melissa Sneaker Ulitsa | F8: 51 | G8: https://images.tcdn.com.br/img/img_prod/995386/mini_melissa_sneaker_ulitsa_51_1_5e5f7609830a0799200b29b8bf3ff639.jpeg | H8: https://images.tcdn.com.br/img/img_prod/995386/mini_melissa_sneaker_ulitsa_51_2_9bddb004e771ff5a8f461747956cc594.jpeg | I8: https://images.tcdn.com.br/img/img_prod/995386/mini_melissa_sneaker_ulitsa_51_4_ffc8b53376c8b1bbc0a2642e3542246b.jpeg | J8: https://images.tcdn.com.br/img/img_prod/995386/mini_melissa_sneaker_ulitsa_51_4_42b10670ae1aef66a526d131101386fc.jpg | K8: 65.00 | L8: 500 | M8: 0.00 | N8: 0 | O8: 0 | P8: Não | S8: 0.00 | T8: Não | U8: Não | V8: Não | W8: 72 | X8: Melissa | Y8: ULITSA | Z8: P51 | AA8: 51 | AB8: 7 dias após o recebimento do produto | AE8: 33.67 | AF8: 0.00 | AG8: Imediata | AJ8: 20 | AK8: 15 | AL8: 10 | AM8: 45322 | AN8: 45411 | AP8: Melissas novas, seminovas e usadas. Em ótimas condições de conservação. Todas higienizadas.Moda circular sustentável!Porque uma melissa bem cuidada é para sempre!? | AS8: https://www.minhamania.net/mini-melissa/mini-melissa-sneaker-ulitsa | AT8: https://images.tcdn.com.br/img/img_prod/995386/mini_melissa_sneaker_ulitsa_51_5_48c06e8e2d4daa3c6722be83110b6e80.jpg | AU8: Infantil
